Workbook

Sheet Start Here
A1: FreshTurn Operations
A2: Everything for running the business in one file. Works in Excel and Google Sheets.
A4: HOW THE FILE WORKS
A5: Dark blue headers | B5: You type in these columns.
A6: Grey headers / grey cells | B6: Worked out automatically. Don't type in them.
A7: Dropdowns | B7: Most columns have a dropdown list (IDs, Y/N, statuses). Use them so the totals work.
A8: Example rows | B8: Rows marked 'EXAMPLE' show how to fill things in. Delete or overwrite them when you start for real.
A9: Door / key safe codes | B9: Never put codes in this file. Keep them in a password manager (e.g. Bitwarden, free) and share only with the cleaner who needs them.
A11: EVERY CLEAN
A12: 1. Cleans Log | B12: Add a row: date, property, cleaner, status. Charges and cleaner pay are calculated for you.
A13: 2. Stock | B13: Cleaner texts you the counts (or fills in the Stock form). Update 'Count now'. Anything at or below the reorder level turns red.
A14: 3. Damage | B14: Anything broken or missing? Add it to Damage the same day and send the host photos. Platforms only allow claims for 14 days.
A16: EVERY WEEK (Friday)
A17: 4. Cleaner Pay | B17: Add a row for each cleaner for the week that just ended. It totals their jobs. Pay them, then fill in 'Paid date'.
A18: 5. Shopping | B18: Check Stock for red items. Buy them (one shop for all properties), log each purchase in Purchases, keep the receipt photo.
A19: 6. Dashboard | B19: Check the alerts box. Everything in it should be zero or dealt with.
A21: EVERY MONTH (1st)
A22: 7. Invoices | B22: Add a row per host for last month. Use Invoice Builder to see the itemised list, copy it into your invoicing app (or PDF) and send.
A23: 8. Expenses | B23: Log running costs (insurance, phone, software, mileage). These reduce your tax bill.
A24: 9. Dashboard | B24: Pick last month: check profit, how much you keep per clean and your effective hourly rate.
A26: NEW PROPERTY
A27: Steps | B27: Add the host to Hosts, the property to Properties (price fills in from Settings, or type an agreed price), then add its stock items to Stock using the template rows.
A29: TABS
A30: Dashboard | B30: Monthly numbers, tax year totals, VAT threshold tracker and alerts.
A31: Cleans Log | B31: One row per clean. The heart of the system.
A32: Properties / Hosts / Cleaners | B32: Who and where.
A33: Stock / Supplies | B33: What each property should have, what it has now, and what everything costs.
A34: Purchases | B34: Everything you buy for a property. Marks what to recharge to the host (+10%) and checks approval and receipts.
A35: Damage | B35: Guest damage with claim deadlines.
A36: Invoices / Invoice Builder | B36: Monthly invoices per host and whether they're paid.
A37: Cleaner Pay | B37: Weekly pay per cleaner.
A38: Expenses | B38: Your running costs for tax.
A39: Price Calculator | B39: Work out a price for a new property from the hours it takes.
A40: Settings | B40: Prices, cleaner pay, markup, approval limits and other rules. Change them here and everything updates.

Sheet Dashboard
A1: Dashboard
A2: Pick a month and a tax year. UK tax years run 6 April to 5 April.
B4: Month | C4: 46296
B5: Tax year | C5: 2026/27
B7: THIS MONTH | E7: NEEDS ATTENTION NOW
B8: Completed cleans | C8: =COUNTIFS('Cleans Log'!$Q$5:$Q$1004,$C$4,'Cleans Log'!$D$5:$D$1004,"Completed") -> 3 | E8: Stock items to reorder | F8: =COUNTIF(Stock!$H$5:$H$504,"REORDER") -> 4
B9: Deep cleans | C9: =COUNTIFS('Cleans Log'!$Q$5:$Q$1004,$C$4,'Cleans Log'!$D$5:$D$1004,"Deep clean") -> 0 | E9: Stock not counted yet | F9: =COUNTIF(Stock!$H$5:$H$504,"Count it") -> 0
B10: Cleaning income | C10: =SUMIFS('Cleans Log'!$N$5:$N$1004,'Cleans Log'!$Q$5:$Q$1004,$C$4) -> 225 | E10: Damage: tell host / claim soon / missed | F10: =COUNTIF(Damage!$N$5:$N$304,"TELL HOST")+COUNTIF(Damage!$N$5:$N$304,"Claim soon")+COUNTIF(Damage!$N$5:$N$304,"Deadline passed") -> 0
B11: Items recharged to hosts | C11: =SUMIFS(Purchases!$N$5:$N$1004,Purchases!$P$5:$P$1004,$C$4) -> 7.04 | E11: Purchases needing approval or receipt | F11: =COUNTIFS(Purchases!$O$5:$O$1004,"<>OK",Purchases!$A$5:$A$1004,"<>") -> 0
B12: Total to invoice | C12: =C10+C11 -> 232.04 | E12: Cleaners to pay | F12: =COUNTIF('Cleaner Pay'!$J$5:$J$504,"PAY NOW") -> 0
B13: Cleaner pay | C13: =SUMIFS('Cleans Log'!$O$5:$O$1004,'Cleans Log'!$Q$5:$Q$1004,$C$4) -> 147.5 | E13: Overdue invoices | F13: =COUNTIF(Invoices!$L$7:$L$306,"OVERDUE") -> 0
B14: Purchases (cost) | C14: =SUMIFS(Purchases!$F$5:$F$1004,Purchases!$P$5:$P$1004,$C$4) -> 6.4 | E14: Money owed to you | F14: =Invoices!$B$4 -> 232.04
B15: Running costs | C15: =SUMIFS(Expenses!$G$5:$G$504,Expenses!$I$5:$I$504,$C$4) -> 13.4 | E15: Cleans with no photos sent | F15: =COUNTIFS('Cleans Log'!$D$5:$D$1004,"Completed",'Cleans Log'!$J$5:$J$1004,"<>Y") -> 0
B16: PROFIT | C16: =C12-C13-C14-C15 -> 64.74
B17: You keep per clean (after cleaner pay) | C17: =IFERROR((C10-C13)/(C8+C9),0) -> 25.833333 | E17: TAX YEAR (for Self Assessment)
B18: Hours cleaned | C18: =SUMIFS('Cleans Log'!$L$5:$L$1004,'Cleans Log'!$Q$5:$Q$1004,$C$4) -> 7.5833333 | E18: Income | F18: =SUMIFS('Cleans Log'!$N$5:$N$1004,'Cleans Log'!$T$5:$T$1004,$C$5)+SUMIFS(Purchases!$N$5:$N$1004,Purchases!$R$5:$R$1004,$C$5) -> 232.04
B19: Income per cleaning hour | C19: =IFERROR(C10/C18,0) -> 29.67033 | E19: Cleaner pay | F19: =SUMIFS('Cleans Log'!$O$5:$O$1004,'Cleans Log'!$T$5:$T$1004,$C$5) -> 147.5
E20: Purchases | F20: =SUMIFS(Purchases!$F$5:$F$1004,Purchases!$R$5:$R$1004,$C$5) -> 6.4
E21: Running costs (incl. mileage) | F21: =SUMIFS(Expenses!$G$5:$G$504,Expenses!$H$5:$H$504,$C$5) -> 13.4
B22: BY PROPERTY (this month) | C22: You keep (£) | E22: Profit | F22: =F18-F19-F20-F21 -> 64.74
B23: =IF(Properties!$A$5="","",Properties!$A$5&" "&Properties!$B$5) -> P001 First client (EXAMPLE) | C23: =IF(Properties!$A$5="","",SUMIFS('Cleans Log'!$P$5:$P$1004,'Cleans Log'!$B$5:$B$1004,Properties!$A$5,'Cleans Log'!$Q$5:$Q$1004,$C$4)) -> 77.5 | E23: Put aside for tax | F23: =MAX(0,F22)*Settings!$B$14 -> 16.185
B24: =IF(Properties!$A$6="","",Properties!$A$6&" "&Properties!$B$6) | C24: =IF(Properties!$A$6="","",SUMIFS('Cleans Log'!$P$5:$P$1004,'Cleans Log'!$B$5:$B$1004,Properties!$A$6,'Cleans Log'!$Q$5:$Q$1004,$C$4))
B25: =IF(Properties!$A$7="","",Properties!$A$7&" "&Properties!$B$7) | C25: =IF(Properties!$A$7="","",SUMIFS('Cleans Log'!$P$5:$P$1004,'Cleans Log'!$B$5:$B$1004,Properties!$A$7,'Cleans Log'!$Q$5:$Q$1004,$C$4)) | E25: VAT THRESHOLD (rolling 12 months)
B26: =IF(Properties!$A$8="","",Properties!$A$8&" "&Properties!$B$8) | C26: =IF(Properties!$A$8="","",SUMIFS('Cleans Log'!$P$5:$P$1004,'Cleans Log'!$B$5:$B$1004,Properties!$A$8,'Cleans Log'!$Q$5:$Q$1004,$C$4)) | E26: Income in the last 12 months | F26: =SUMIFS('Cleans Log'!$N$5:$N$1004,'Cleans Log'!$A$5:$A$1004,">"&EDATE(TODAY(),-12))+SUMIFS(Purchases!$N$5:$N$1004,Purchases!$A$5:$A$1004,">"&EDATE(TODAY(),-12)) -> 232.04
B27: =IF(Properties!$A$9="","",Properties!$A$9&" "&Properties!$B$9) | C27: =IF(Properties!$A$9="","",SUMIFS('Cleans Log'!$P$5:$P$1004,'Cleans Log'!$B$5:$B$1004,Properties!$A$9,'Cleans Log'!$Q$5:$Q$1004,$C$4)) | E27: % of VAT threshold | F27: =IFERROR(F26/Settings!$B$15,0) -> 0.0025782222
B28: =IF(Properties!$A$10="","",Properties!$A$10&" "&Properties!$B$10) | C28: =IF(Properties!$A$10="","",SUMIFS('Cleans Log'!$P$5:$P$1004,'Cleans Log'!$B$5:$B$1004,Properties!$A$10,'Cleans Log'!$Q$5:$Q$1004,$C$4)) | E28: What to do | F28: =IF(F27>=1,"Register for VAT now (within 30 days)",IF(F27>=0.8,"Getting close: talk to an accountant","Fine")) -> Fine
B29: =IF(Properties!$A$11="","",Properties!$A$11&" "&Properties!$B$11) | C29: =IF(Properties!$A$11="","",SUMIFS('Cleans Log'!$P$5:$P$1004,'Cleans Log'!$B$5:$B$1004,Properties!$A$11,'Cleans Log'!$Q$5:$Q$1004,$C$4))
B30: =IF(Properties!$A$12="","",Properties!$A$12&" "&Properties!$B$12) | C30: =IF(Properties!$A$12="","",SUMIFS('Cleans Log'!$P$5:$P$1004,'Cleans Log'!$B$5:$B$1004,Properties!$A$12,'Cleans Log'!$Q$5:$Q$1004,$C$4))
B31: =IF(Properties!$A$13="","",Properties!$A$13&" "&Properties!$B$13) | C31: =IF(Properties!$A$13="","",SUMIFS('Cleans Log'!$P$5:$P$1004,'Cleans Log'!$B$5:$B$1004,Properties!$A$13,'Cleans Log'!$Q$5:$Q$1004,$C$4))
B32: =IF(Properties!$A$14="","",Properties!$A$14&" "&Properties!$B$14) | C32: =IF(Properties!$A$14="","",SUMIFS('Cleans Log'!$P$5:$P$1004,'Cleans Log'!$B$5:$B$1004,Properties!$A$14,'Cleans Log'!$Q$5:$Q$1004,$C$4))
B33: =IF(Properties!$A$15="","",Properties!$A$15&" "&Properties!$B$15) | C33: =IF(Properties!$A$15="","",SUMIFS('Cleans Log'!$P$5:$P$1004,'Cleans Log'!$B$5:$B$1004,Properties!$A$15,'Cleans Log'!$Q$5:$Q$1004,$C$4))
B34: =IF(Properties!$A$16="","",Properties!$A$16&" "&Properties!$B$16) | C34: =IF(Properties!$A$16="","",SUMIFS('Cleans Log'!$P$5:$P$1004,'Cleans Log'!$B$5:$B$1004,Properties!$A$16,'Cleans Log'!$Q$5:$Q$1004,$C$4))
B35: =IF(Properties!$A$17="","",Properties!$A$17&" "&Properties!$B$17) | C35: =IF(Properties!$A$17="","",SUMIFS('Cleans Log'!$P$5:$P$1004,'Cleans Log'!$B$5:$B$1004,Properties!$A$17,'Cleans Log'!$Q$5:$Q$1004,$C$4))
B36: =IF(Properties!$A$18="","",Properties!$A$18&" "&Properties!$B$18) | C36: =IF(Properties!$A$18="","",SUMIFS('Cleans Log'!$P$5:$P$1004,'Cleans Log'!$B$5:$B$1004,Properties!$A$18,'Cleans Log'!$Q$5:$Q$1004,$C$4))
B37: =IF(Properties!$A$19="","",Properties!$A$19&" "&Properties!$B$19) | C37: =IF(Properties!$A$19="","",SUMIFS('Cleans Log'!$P$5:$P$1004,'Cleans Log'!$B$5:$B$1004,Properties!$A$19,'Cleans Log'!$Q$5:$Q$1004,$C$4))

Sheet Cleans Log
A1: Cleans Log
A2: One row per visit. Status: Completed, Deep clean, Late cancel (host charged 50%), Cancelled (no charge), Re-clean (free fix).
A4: Date | B4: Prop ID | C4: Cleaner ID | D4: Status | E4: Start | F4: Finish | G4: Rush (Y/N) | H4: Hot tub (Y/N) | I4: Other extra (£) | J4: Photos sent (Y/N) | K4: Issues / notes | L4: Hours | M4: Host ID | N4: Charge to host (£) | O4: Cleaner pay (£) | P4: You keep (£) | Q4: Month | R4: Work week ends (Fri) | S4: Invoice line # | T4: Tax year
A5: 46298 | B5: P001 | C5: C001 | D5: Completed | E5: 0.46875 | F5: 0.57638889 | G5: N | H5: N | J5: Y | K5: EXAMPLE | L5: =IF(OR($E5="",$F5=""),"",MOD($F5-$E5,1)*24) -> 2.5833333 | M5: =IF($B5="","",IFERROR(INDEX(Properties!$D$5:$D$104,MATCH($B5,Properties!$A$5:$A$104,0)),"?")) -> H001 | N5: =IF($B5="","",IFERROR(IF($D5="Completed",INDEX(Properties!$I$5:$I$104,MATCH($B5,Properties!$A$5:$A$104,0))*(1+IF($G5="Y",Settings!$B$8,0))+IF($H5="Y",Settings!$B$7,0)+N($I5),IF($D5="Deep clean",INDEX(Settings!$E$22:$E$26,MATCH(MIN(INDEX(Properties!$E$5:$E$104,MATCH($B5,Properties!$A$5:$A$104,0)),4),Settings!$A$22:$A$26,0))+N($I5),IF($D5="Late cancel",INDEX(Properties!$I$5:$I$104,MATCH($B5,Properties!$A$5:$A$104,0))*Settings!$B$10,0))),0)) -> 60 | O5: =IF($B5="","",IFERROR(IF($D5="Completed",INDEX(Properties!$L$5:$L$104,MATCH($B5,Properties!$A$5:$A$104,0))+IF($G5="Y",INDEX(Properties!$I$5:$I$104,MATCH($B5,Properties!$A$5:$A$104,0))*Settings!$B$8*Settings!$B$9,0)+IF($H5="Y",Settings!$B$7*Settings!$B$9,0)+N($I5)*Settings!$B$9,IF($D5="Deep clean",INDEX(Settings!$E$22:$E$26,MATCH(MIN(INDEX(Properties!$E$5:$E$104,MATCH($B5,Properties!$A$5:$A$104,0)),4),Settings!$A$22:$A$26,0))*Settings!$B$19+N($I5)*Settings!$B$9,IF($D5="Late cancel",INDEX(Properties!$L$5:$L$104,MATCH($B5,Properties!$A$5:$A$104,0))*Settings!$B$11,0))),0)) -> 40 | P5: =IF($B5="","",$N5-$O5) -> 20 | Q5: =IF($A5="","",DATE(YEAR($A5),MONTH($A5),1)) -> 46296 | R5: =IF($A5="","",$A5+MOD(6-WEEKDAY($A5),7)) -> 46304 | S5: =IF($B5="","",IF(AND($M5='Invoice Builder'!$C$5,$Q5='Invoice Builder'!$C$6,N($N5)>0),COUNTIFS($M$5:$M5,'Invoice Builder'!$C$5,$Q$5:$Q5,'Invoice Builder'!$C$6,$N$5:$N5,">0"),"")) -> 1 | T5: =IF($A5="","",IF($A5>=DATE(YEAR($A5),4,6),YEAR($A5)&"/"&RIGHT(YEAR($A5)+1,2),YEAR($A5)-1&"/"&RIGHT(YEAR($A5),2))) -> 2026/27
A6: 46305 | B6: P001 | C6: C001 | D6: Completed | E6: 0.46180556 | F6: 0.56597222 | G6: N | H6: N | J6: Y | K6: EXAMPLE: bulb replaced | L6: =IF(OR($E6="",$F6=""),"",MOD($F6-$E6,1)*24) -> 2.5 | M6: =IF($B6="","",IFERROR(INDEX(Properties!$D$5:$D$104,MATCH($B6,Properties!$A$5:$A$104,0)),"?")) -> H001 | N6: =IF($B6="","",IFERROR(IF($D6="Completed",INDEX(Properties!$I$5:$I$104,MATCH($B6,Properties!$A$5:$A$104,0))*(1+IF($G6="Y",Settings!$B$8,0))+IF($H6="Y",Settings!$B$7,0)+N($I6),IF($D6="Deep clean",INDEX(Settings!$E$22:$E$26,MATCH(MIN(INDEX(Properties!$E$5:$E$104,MATCH($B6,Properties!$A$5:$A$104,0)),4),Settings!$A$22:$A$26,0))+N($I6),IF($D6="Late cancel",INDEX(Properties!$I$5:$I$104,MATCH($B6,Properties!$A$5:$A$104,0))*Settings!$B$10,0))),0)) -> 60 | O6: =IF($B6="","",IFERROR(IF($D6="Completed",INDEX(Properties!$L$5:$L$104,MATCH($B6,Properties!$A$5:$A$104,0))+IF($G6="Y",INDEX(Properties!$I$5:$I$104,MATCH($B6,Properties!$A$5:$A$104,0))*Settings!$B$8*Settings!$B$9,0)+IF($H6="Y",Settings!$B$7*Settings!$B$9,0)+N($I6)*Settings!$B$9,IF($D6="Deep clean",INDEX(Settings!$E$22:$E$26,MATCH(MIN(INDEX(Properties!$E$5:$E$104,MATCH($B6,Properties!$A$5:$A$104,0)),4),Settings!$A$22:$A$26,0))*Settings!$B$19+N($I6)*Settings!$B$9,IF($D6="Late cancel",INDEX(Properties!$L$5:$L$104,MATCH($B6,Properties!$A$5:$A$104,0))*Settings!$B$11,0))),0)) -> 40 | P6: =IF($B6="","",$N6-$O6) -> 20 | Q6: =IF($A6="","",DATE(YEAR($A6),MONTH($A6),1)) -> 46296 | R6: =IF($A6="","",$A6+MOD(6-WEEKDAY($A6),7)) -> 46311 | S6: =IF($B6="","",IF(AND($M6='Invoice Builder'!$C$5,$Q6='Invoice Builder'!$C$6,N($N6)>0),COUNTIFS($M$5:$M6,'Invoice Builder'!$C$5,$Q$5:$Q6,'Invoice Builder'!$C$6,$N$5:$N6,">0"),"")) -> 2 | T6: =IF($A6="","",IF($A6>=DATE(YEAR($A6),4,6),YEAR($A6)&"/"&RIGHT(YEAR($A6)+1,2),YEAR($A6)-1&"/"&RIGHT(YEAR($A6),2))) -> 2026/27
A7: 46312 | B7: P001 | C7: C002 | D7: Completed | E7: 0.52083333 | F7: 0.625 | G7: Y | H7: N | J7: Y | K7: EXAMPLE: booked same morning | L7: =IF(OR($E7="",$F7=""),"",MOD($F7-$E7,1)*24) -> 2.5 | M7: =IF($B7="","",IFERROR(INDEX(Properties!$D$5:$D$104,MATCH($B7,Properties!$A$5:$A$104,0)),"?")) -> H001 | N7: =IF($B7="","",IFERROR(IF($D7="Completed",INDEX(Properties!$I$5:$I$104,MATCH($B7,Properties!$A$5:$A$104,0))*(1+IF($G7="Y",Settings!$B$8,0))+IF($H7="Y",Settings!$B$7,0)+N($I7),IF($D7="Deep clean",INDEX(Settings!$E$22:$E$26,MATCH(MIN(INDEX(Properties!$E$5:$E$104,MATCH($B7,Properties!$A$5:$A$104,0)),4),Settings!$A$22:$A$26,0))+N($I7),IF($D7="Late cancel",INDEX(Properties!$I$5:$I$104,MATCH($B7,Properties!$A$5:$A$104,0))*Settings!$B$10,0))),0)) -> 75 | O7: =IF($B7="","",IFERROR(IF($D7="Completed",INDEX(Properties!$L$5:$L$104,MATCH($B7,Properties!$A$5:$A$104,0))+IF($G7="Y",INDEX(Properties!$I$5:$I$104,MATCH($B7,Properties!$A$5:$A$104,0))*Settings!$B$8*Settings!$B$9,0)+IF($H7="Y",Settings!$B$7*Settings!$B$9,0)+N($I7)*Settings!$B$9,IF($D7="Deep clean",INDEX(Settings!$E$22:$E$26,MATCH(MIN(INDEX(Properties!$E$5:$E$104,MATCH($B7,Properties!$A$5:$A$104,0)),4),Settings!$A$22:$A$26,0))*Settings!$B$19+N($I7)*Settings!$B$9,IF($D7="Late cancel",INDEX(Properties!$L$5:$L$104,MATCH($B7,Properties!$A$5:$A$104,0))*Settings!$B$11,0))),0)) -> 47.5 | P7: =IF($B7="","",$N7-$O7) -> 27.5 | Q7: =IF($A7="","",DATE(YEAR($A7),MONTH($A7),1)) -> 46296 | R7: =IF($A7="","",$A7+MOD(6-WEEKDAY($A7),7)) -> 46318 | S7: =IF($B7="","",IF(AND($M7='Invoice Builder'!$C$5,$Q7='Invoice Builder'!$C$6,N($N7)>0),COUNTIFS($M$5:$M7,'Invoice Builder'!$C$5,$Q$5:$Q7,'Invoice Builder'!$C$6,$N$5:$N7,">0"),"")) -> 3 | T7: =IF($A7="","",IF($A7>=DATE(YEAR($A7),4,6),YEAR($A7)&"/"&RIGHT(YEAR($A7)+1,2),YEAR($A7)-1&"/"&RIGHT(YEAR($A7),2))) -> 2026/27
A8: 46319 | B8: P001 | C8: C001 | D8: Late cancel | G8: N | H8: N | K8: EXAMPLE: guest extended, host told us at 9am | L8: =IF(OR($E8="",$F8=""),"",MOD($F8-$E8,1)*24) | M8: =IF($B8="","",IFERROR(INDEX(Properties!$D$5:$D$104,MATCH($B8,Properties!$A$5:$A$104,0)),"?")) -> H001 | N8: =IF($B8="","",IFERROR(IF($D8="Completed",INDEX(Properties!$I$5:$I$104,MATCH($B8,Properties!$A$5:$A$104,0))*(1+IF($G8="Y",Settings!$B$8,0))+IF($H8="Y",Settings!$B$7,0)+N($I8),IF($D8="Deep clean",INDEX(Settings!$E$22:$E$26,MATCH(MIN(INDEX(Properties!$E$5:$E$104,MATCH($B8,Properties!$A$5:$A$104,0)),4),Settings!$A$22:$A$26,0))+N($I8),IF($D8="Late cancel",INDEX(Properties!$I$5:$I$104,MATCH($B8,Properties!$A$5:$A$104,0))*Settings!$B$10,0))),0)) -> 30 | O8: =IF($B8="","",IFERROR(IF($D8="Completed",INDEX(Properties!$L$5:$L$104,MATCH($B8,Properties!$A$5:$A$104,0))+IF($G8="Y",INDEX(Properties!$I$5:$I$104,MATCH($B8,Properties!$A$5:$A$104,0))*Settings!$B$8*Settings!$B$9,0)+IF($H8="Y",Settings!$B$7*Settings!$B$9,0)+N($I8)*Settings!$B$9,IF($D8="Deep clean",INDEX(Settings!$E$22:$E$26,MATCH(MIN(INDEX(Properties!$E$5:$E$104,MATCH($B8,Properties!$A$5:$A$104,0)),4),Settings!$A$22:$A$26,0))*Settings!$B$19+N($I8)*Settings!$B$9,IF($D8="Late cancel",INDEX(Properties!$L$5:$L$104,MATCH($B8,Properties!$A$5:$A$104,0))*Settings!$B$11,0))),0)) -> 20 | P8: =IF($B8="","",$N8-$O8) -> 10 | Q8: =IF($A8="","",DATE(YEAR($A8),MONTH($A8),1)) -> 46296 | R8: =IF($A8="","",$A8+MOD(6-WEEKDAY($A8),7)) -> 46325 | S8: =IF($B8="","",IF(AND($M8='Invoice Builder'!$C$5,$Q8='Invoice Builder'!$C$6,N($N8)>0),COUNTIFS($M$5:$M8,'Invoice Builder'!$C$5,$Q$5:$Q8,'Invoice Builder'!$C$6,$N$5:$N8,">0"),"")) -> 4 | T8: =IF($A8="","",IF($A8>=DATE(YEAR($A8),4,6),YEAR($A8)&"/"&RIGHT(YEAR($A8)+1,2),YEAR($A8)-1&"/"&RIGHT(YEAR($A8),2))) -> 2026/27
L9: =IF(OR($E9="",$F9=""),"",MOD($F9-$E9,1)*24) | M9: =IF($B9="","",IFERROR(INDEX(Properties!$D$5:$D$104,MATCH($B9,Properties!$A$5:$A$104,0)),"?")) | N9: =IF($B9="","",IFERROR(IF($D9="Completed",INDEX(Properties!$I$5:$I$104,MATCH($B9,Properties!$A$5:$A$104,0))*(1+IF($G9="Y",Settings!$B$8,0))+IF($H9="Y",Settings!$B$7,0)+N($I9),IF($D9="Deep clean",INDEX(Settings!$E$22:$E$26,MATCH(MIN(INDEX(Properties!$E$5:$E$104,MATCH($B9,Properties!$A$5:$A$104,0)),4),Settings!$A$22:$A$26,0))+N($I9),IF($D9="Late cancel",INDEX(Properties!$I$5:$I$104,MATCH($B9,Properties!$A$5:$A$104,0))*Settings!$B$10,0))),0)) | O9: =IF($B9="","",IFERROR(IF($D9="Completed",INDEX(Properties!$L$5:$L$104,MATCH($B9,Properties!$A$5:$A$104,0))+IF($G9="Y",INDEX(Properties!$I$5:$I$104,MATCH($B9,Properties!$A$5:$A$104,0))*Settings!$B$8*Settings!$B$9,0)+IF($H9="Y",Settings!$B$7*Settings!$B$9,0)+N($I9)*Settings!$B$9,IF($D9="Deep clean",INDEX(Settings!$E$22:$E$26,MATCH(MIN(INDEX(Properties!$E$5:$E$104,MATCH($B9,Properties!$A$5:$A$104,0)),4),Settings!$A$22:$A$26,0))*Settings!$B$19+N($I9)*Settings!$B$9,IF($D9="Late cancel",INDEX(Properties!$L$5:$L$104,MATCH($B9,Properties!$A$5:$A$104,0))*Settings!$B$11,0))),0)) | P9: =IF($B9="","",$N9-$O9) | Q9: =IF($A9="","",DATE(YEAR($A9),MONTH($A9),1)) | R9: =IF($A9="","",$A9+MOD(6-WEEKDAY($A9),7)) | S9: =IF($B9="","",IF(AND($M9='Invoice Builder'!$C$5,$Q9='Invoice Builder'!$C$6,N($N9)>0),COUNTIFS($M$5:$M9,'Invoice Builder'!$C$5,$Q$5:$Q9,'Invoice Builder'!$C$6,$N$5:$N9,">0"),"")) | T9: =IF($A9="","",IF($A9>=DATE(YEAR($A9),4,6),YEAR($A9)&"/"&RIGHT(YEAR($A9)+1,2),YEAR($A9)-1&"/"&RIGHT(YEAR($A9),2)))
L10: =IF(OR($E10="",$F10=""),"",MOD($F10-$E10,1)*24) | M10: =IF($B10="","",IFERROR(INDEX(Properties!$D$5:$D$104,MATCH($B10,Properties!$A$5:$A$104,0)),"?")) | N10: =IF($B10="","",IFERROR(IF($D10="Completed",INDEX(Properties!$I$5:$I$104,MATCH($B10,Properties!$A$5:$A$104,0))*(1+IF($G10="Y",Settings!$B$8,0))+IF($H10="Y",Settings!$B$7,0)+N($I10),IF($D10="Deep clean",INDEX(Settings!$E$22:$E$26,MATCH(MIN(INDEX(Properties!$E$5:$E$104,MATCH($B10,Properties!$A$5:$A$104,0)),4),Settings!$A$22:$A$26,0))+N($I10),IF($D10="Late cancel",INDEX(Properties!$I$5:$I$104,MATCH($B10,Properties!$A$5:$A$104,0))*Settings!$B$10,0))),0)) | O10: =IF($B10="","",IFERROR(IF($D10="Completed",INDEX(Properties!$L$5:$L$104,MATCH($B10,Properties!$A$5:$A$104,0))+IF($G10="Y",INDEX(Properties!$I$5:$I$104,MATCH($B10,Properties!$A$5:$A$104,0))*Settings!$B$8*Settings!$B$9,0)+IF($H10="Y",Settings!$B$7*Settings!$B$9,0)+N($I10)*Settings!$B$9,IF($D10="Deep clean",INDEX(Settings!$E$22:$E$26,MATCH(MIN(INDEX(Properties!$E$5:$E$104,MATCH($B10,Properties!$A$5:$A$104,0)),4),Settings!$A$22:$A$26,0))*Settings!$B$19+N($I10)*Settings!$B$9,IF($D10="Late cancel",INDEX(Properties!$L$5:$L$104,MATCH($B10,Properties!$A$5:$A$104,0))*Settings!$B$11,0))),0)) | P10: =IF($B10="","",$N10-$O10) | Q10: =IF($A10="","",DATE(YEAR($A10),MONTH($A10),1)) | R10: =IF($A10="","",$A10+MOD(6-WEEKDAY($A10),7)) | S10: =IF($B10="","",IF(AND($M10='Invoice Builder'!$C$5,$Q10='Invoice Builder'!$C$6,N($N10)>0),COUNTIFS($M$5:$M10,'Invoice Builder'!$C$5,$Q$5:$Q10,'Invoice Builder'!$C$6,$N$5:$N10,">0"),"")) | T10: =IF($A10="","",IF($A10>=DATE(YEAR($A10),4,6),YEAR($A10)&"/"&RIGHT(YEAR($A10)+1,2),YEAR($A10)-1&"/"&RIGHT(YEAR($A10),2)))
L11: =IF(OR($E11="",$F11=""),"",MOD($F11-$E11,1)*24) | M11: =IF($B11="","",IFERROR(INDEX(Properties!$D$5:$D$104,MATCH($B11,Properties!$A$5:$A$104,0)),"?")) | N11: =IF($B11="","",IFERROR(IF($D11="Completed",INDEX(Properties!$I$5:$I$104,MATCH($B11,Properties!$A$5:$A$104,0))*(1+IF($G11="Y",Settings!$B$8,0))+IF($H11="Y",Settings!$B$7,0)+N($I11),IF($D11="Deep clean",INDEX(Settings!$E$22:$E$26,MATCH(MIN(INDEX(Properties!$E$5:$E$104,MATCH($B11,Properties!$A$5:$A$104,0)),4),Settings!$A$22:$A$26,0))+N($I11),IF($D11="Late cancel",INDEX(Properties!$I$5:$I$104,MATCH($B11,Properties!$A$5:$A$104,0))*Settings!$B$10,0))),0)) | O11: =IF($B11="","",IFERROR(IF($D11="Completed",INDEX(Properties!$L$5:$L$104,MATCH($B11,Properties!$A$5:$A$104,0))+IF($G11="Y",INDEX(Properties!$I$5:$I$104,MATCH($B11,Properties!$A$5:$A$104,0))*Settings!$B$8*Settings!$B$9,0)+IF($H11="Y",Settings!$B$7*Settings!$B$9,0)+N($I11)*Settings!$B$9,IF($D11="Deep clean",INDEX(Settings!$E$22:$E$26,MATCH(MIN(INDEX(Properties!$E$5:$E$104,MATCH($B11,Properties!$A$5:$A$104,0)),4),Settings!$A$22:$A$26,0))*Settings!$B$19+N($I11)*Settings!$B$9,IF($D11="Late cancel",INDEX(Properties!$L$5:$L$104,MATCH($B11,Properties!$A$5:$A$104,0))*Settings!$B$11,0))),0)) | P11: =IF($B11="","",$N11-$O11) | Q11: =IF($A11="","",DATE(YEAR($A11),MONTH($A11),1)) | R11: =IF($A11="","",$A11+MOD(6-WEEKDAY($A11),7)) | S11: =IF($B11="","",IF(AND($M11='Invoice Builder'!$C$5,$Q11='Invoice Builder'!$C$6,N($N11)>0),COUNTIFS($M$5:$M11,'Invoice Builder'!$C$5,$Q$5:$Q11,'Invoice Builder'!$C$6,$N$5:$N11,">0"),"")) | T11: =IF($A11="","",IF($A11>=DATE(YEAR($A11),4,6),YEAR($A11)&"/"&RIGHT(YEAR($A11)+1,2),YEAR($A11)-1&"/"&RIGHT(YEAR($A11),2)))
L12: =IF(OR($E12="",$F12=""),"",MOD($F12-$E12,1)*24) | M12: =IF($B12="","",IFERROR(INDEX(Properties!$D$5:$D$104,MATCH($B12,Properties!$A$5:$A$104,0)),"?")) | N12: =IF($B12="","",IFERROR(IF($D12="Completed",INDEX(Properties!$I$5:$I$104,MATCH($B12,Properties!$A$5:$A$104,0))*(1+IF($G12="Y",Settings!$B$8,0))+IF($H12="Y",Settings!$B$7,0)+N($I12),IF($D12="Deep clean",INDEX(Settings!$E$22:$E$26,MATCH(MIN(INDEX(Properties!$E$5:$E$104,MATCH($B12,Properties!$A$5:$A$104,0)),4),Settings!$A$22:$A$26,0))+N($I12),IF($D12="Late cancel",INDEX(Properties!$I$5:$I$104,MATCH($B12,Properties!$A$5:$A$104,0))*Settings!$B$10,0))),0)) | O12: =IF($B12="","",IFERROR(IF($D12="Completed",INDEX(Properties!$L$5:$L$104,MATCH($B12,Properties!$A$5:$A$104,0))+IF($G12="Y",INDEX(Properties!$I$5:$I$104,MATCH($B12,Properties!$A$5:$A$104,0))*Settings!$B$8*Settings!$B$9,0)+IF($H12="Y",Settings!$B$7*Settings!$B$9,0)+N($I12)*Settings!$B$9,IF($D12="Deep clean",INDEX(Settings!$E$22:$E$26,MATCH(MIN(INDEX(Properties!$E$5:$E$104,MATCH($B12,Properties!$A$5:$A$104,0)),4),Settings!$A$22:$A$26,0))*Settings!$B$19+N($I12)*Settings!$B$9,IF($D12="Late cancel",INDEX(Properties!$L$5:$L$104,MATCH($B12,Properties!$A$5:$A$104,0))*Settings!$B$11,0))),0)) | P12: =IF($B12="","",$N12-$O12) | Q12: =IF($A12="","",DATE(YEAR($A12),MONTH($A12),1)) | R12: =IF($A12="","",$A12+MOD(6-WEEKDAY($A12),7)) | S12: =IF($B12="","",IF(AND($M12='Invoice Builder'!$C$5,$Q12='Invoice Builder'!$C$6,N($N12)>0),COUNTIFS($M$5:$M12,'Invoice Builder'!$C$5,$Q$5:$Q12,'Invoice Builder'!$C$6,$N$5:$N12,">0"),"")) | T12: =IF($A12="","",IF($A12>=DATE(YEAR($A12),4,6),YEAR($A12)&"/"&RIGHT(YEAR($A12)+1,2),YEAR($A12)-1&"/"&RIGHT(YEAR($A12),2)))
L13: =IF(OR($E13="",$F13=""),"",MOD($F13-$E13,1)*24) | M13: =IF($B13="","",IFERROR(INDEX(Properties!$D$5:$D$104,MATCH($B13,Properties!$A$5:$A$104,0)),"?")) | N13: =IF($B13="","",IFERROR(IF($D13="Completed",INDEX(Properties!$I$5:$I$104,MATCH($B13,Properties!$A$5:$A$104,0))*(1+IF($G13="Y",Settings!$B$8,0))+IF($H13="Y",Settings!$B$7,0)+N($I13),IF($D13="Deep clean",INDEX(Settings!$E$22:$E$26,MATCH(MIN(INDEX(Properties!$E$5:$E$104,MATCH($B13,Properties!$A$5:$A$104,0)),4),Settings!$A$22:$A$26,0))+N($I13),IF($D13="Late cancel",INDEX(Properties!$I$5:$I$104,MATCH($B13,Properties!$A$5:$A$104,0))*Settings!$B$10,0))),0)) | O13: =IF($B13="","",IFERROR(IF($D13="Completed",INDEX(Properties!$L$5:$L$104,MATCH($B13,Properties!$A$5:$A$104,0))+IF($G13="Y",INDEX(Properties!$I$5:$I$104,MATCH($B13,Properties!$A$5:$A$104,0))*Settings!$B$8*Settings!$B$9,0)+IF($H13="Y",Settings!$B$7*Settings!$B$9,0)+N($I13)*Settings!$B$9,IF($D13="Deep clean",INDEX(Settings!$E$22:$E$26,MATCH(MIN(INDEX(Properties!$E$5:$E$104,MATCH($B13,Properties!$A$5:$A$104,0)),4),Settings!$A$22:$A$26,0))*Settings!$B$19+N($I13)*Settings!$B$9,IF($D13="Late cancel",INDEX(Properties!$L$5:$L$104,MATCH($B13,Properties!$A$5:$A$104,0))*Settings!$B$11,0))),0)) | P13: =IF($B13="","",$N13-$O13) | Q13: =IF($A13="","",DATE(YEAR($A13),MONTH($A13),1)) | R13: =IF($A13="","",$A13+MOD(6-WEEKDAY($A13),7)) | S13: =IF($B13="","",IF(AND($M13='Invoice Builder'!$C$5,$Q13='Invoice Builder'!$C$6,N($N13)>0),COUNTIFS($M$5:$M13,'Invoice Builder'!$C$5,$Q$5:$Q13,'Invoice Builder'!$C$6,$N$5:$N13,">0"),"")) | T13: =IF($A13="","",IF($A13>=DATE(YEAR($A13),4,6),YEAR($A13)&"/"&RIGHT(YEAR($A13)+1,2),YEAR($A13)-1&"/"&RIGHT(YEAR($A13),2)))
L14: =IF(OR($E14="",$F14=""),"",MOD($F14-$E14,1)*24) | M14: =IF($B14="","",IFERROR(INDEX(Properties!$D$5:$D$104,MATCH($B14,Properties!$A$5:$A$104,0)),"?")) | N14: =IF($B14="","",IFERROR(IF($D14="Completed",INDEX(Properties!$I$5:$I$104,MATCH($B14,Properties!$A$5:$A$104,0))*(1+IF($G14="Y",Settings!$B$8,0))+IF($H14="Y",Settings!$B$7,0)+N($I14),IF($D14="Deep clean",INDEX(Settings!$E$22:$E$26,MATCH(MIN(INDEX(Properties!$E$5:$E$104,MATCH($B14,Properties!$A$5:$A$104,0)),4),Settings!$A$22:$A$26,0))+N($I14),IF($D14="Late cancel",INDEX(Properties!$I$5:$I$104,MATCH($B14,Properties!$A$5:$A$104,0))*Settings!$B$10,0))),0)) | O14: =IF($B14="","",IFERROR(IF($D14="Completed",INDEX(Properties!$L$5:$L$104,MATCH($B14,Properties!$A$5:$A$104,0))+IF($G14="Y",INDEX(Properties!$I$5:$I$104,MATCH($B14,Properties!$A$5:$A$104,0))*Settings!$B$8*Settings!$B$9,0)+IF($H14="Y",Settings!$B$7*Settings!$B$9,0)+N($I14)*Settings!$B$9,IF($D14="Deep clean",INDEX(Settings!$E$22:$E$26,MATCH(MIN(INDEX(Properties!$E$5:$E$104,MATCH($B14,Properties!$A$5:$A$104,0)),4),Settings!$A$22:$A$26,0))*Settings!$B$19+N($I14)*Settings!$B$9,IF($D14="Late cancel",INDEX(Properties!$L$5:$L$104,MATCH($B14,Properties!$A$5:$A$104,0))*Settings!$B$11,0))),0)) | P14: =IF($B14="","",$N14-$O14) | Q14: =IF($A14="","",DATE(YEAR($A14),MONTH($A14),1)) | R14: =IF($A14="","",$A14+MOD(6-WEEKDAY($A14),7)) | S14: =IF($B14="","",IF(AND($M14='Invoice Builder'!$C$5,$Q14='Invoice Builder'!$C$6,N($N14)>0),COUNTIFS($M$5:$M14,'Invoice Builder'!$C$5,$Q$5:$Q14,'Invoice Builder'!$C$6,$N$5:$N14,">0"),"")) | T14: =IF($A14="","",IF($A14>=DATE(YEAR($A14),4,6),YEAR($A14)&"/"&RIGHT(YEAR($A14)+1,2),YEAR($A14)-1&"/"&RIGHT(YEAR($A14),2)))
L15: =IF(OR($E15="",$F15=""),"",MOD($F15-$E15,1)*24) | M15: =IF($B15="","",IFERROR(INDEX(Properties!$D$5:$D$104,MATCH($B15,Properties!$A$5:$A$104,0)),"?")) | N15: =IF($B15="","",IFERROR(IF($D15="Completed",INDEX(Properties!$I$5:$I$104,MATCH($B15,Properties!$A$5:$A$104,0))*(1+IF($G15="Y",Settings!$B$8,0))+IF($H15="Y",Settings!$B$7,0)+N($I15),IF($D15="Deep clean",INDEX(Settings!$E$22:$E$26,MATCH(MIN(INDEX(Properties!$E$5:$E$104,MATCH($B15,Properties!$A$5:$A$104,0)),4),Settings!$A$22:$A$26,0))+N($I15),IF($D15="Late cancel",INDEX(Properties!$I$5:$I$104,MATCH($B15,Properties!$A$5:$A$104,0))*Settings!$B$10,0))),0)) | O15: =IF($B15="","",IFERROR(IF($D15="Completed",INDEX(Properties!$L$5:$L$104,MATCH($B15,Properties!$A$5:$A$104,0))+IF($G15="Y",INDEX(Properties!$I$5:$I$104,MATCH($B15,Properties!$A$5:$A$104,0))*Settings!$B$8*Settings!$B$9,0)+IF($H15="Y",Settings!$B$7*Settings!$B$9,0)+N($I15)*Settings!$B$9,IF($D15="Deep clean",INDEX(Settings!$E$22:$E$26,MATCH(MIN(INDEX(Properties!$E$5:$E$104,MATCH($B15,Properties!$A$5:$A$104,0)),4),Settings!$A$22:$A$26,0))*Settings!$B$19+N($I15)*Settings!$B$9,IF($D15="Late cancel",INDEX(Properties!$L$5:$L$104,MATCH($B15,Properties!$A$5:$A$104,0))*Settings!$B$11,0))),0)) | P15: =IF($B15="","",$N15-$O15) | Q15: =IF($A15="","",DATE(YEAR($A15),MONTH($A15),1)) | R15: =IF($A15="","",$A15+MOD(6-WEEKDAY($A15),7)) | S15: =IF($B15="","",IF(AND($M15='Invoice Builder'!$C$5,$Q15='Invoice Builder'!$C$6,N($N15)>0),COUNTIFS($M$5:$M15,'Invoice Builder'!$C$5,$Q$5:$Q15,'Invoice Builder'!$C$6,$N$5:$N15,">0"),"")) | T15: =IF($A15="","",IF($A15>=DATE(YEAR($A15),4,6),YEAR($A15)&"/"&RIGHT(YEAR($A15)+1,2),YEAR($A15)-1&"/"&RIGHT(YEAR($A15),2)))
L16: =IF(OR($E16="",$F16=""),"",MOD($F16-$E16,1)*24) | M16: =IF($B16="","",IFERROR(INDEX(Properties!$D$5:$D$104,MATCH($B16,Properties!$A$5:$A$104,0)),"?")) | N16: =IF($B16="","",IFERROR(IF($D16="Completed",INDEX(Properties!$I$5:$I$104,MATCH($B16,Properties!$A$5:$A$104,0))*(1+IF($G16="Y",Settings!$B$8,0))+IF($H16="Y",Settings!$B$7,0)+N($I16),IF($D16="Deep clean",INDEX(Settings!$E$22:$E$26,MATCH(MIN(INDEX(Properties!$E$5:$E$104,MATCH($B16,Properties!$A$5:$A$104,0)),4),Settings!$A$22:$A$26,0))+N($I16),IF($D16="Late cancel",INDEX(Properties!$I$5:$I$104,MATCH($B16,Properties!$A$5:$A$104,0))*Settings!$B$10,0))),0)) | O16: =IF($B16="","",IFERROR(IF($D16="Completed",INDEX(Properties!$L$5:$L$104,MATCH($B16,Properties!$A$5:$A$104,0))+IF($G16="Y",INDEX(Properties!$I$5:$I$104,MATCH($B16,Properties!$A$5:$A$104,0))*Settings!$B$8*Settings!$B$9,0)+IF($H16="Y",Settings!$B$7*Settings!$B$9,0)+N($I16)*Settings!$B$9,IF($D16="Deep clean",INDEX(Settings!$E$22:$E$26,MATCH(MIN(INDEX(Properties!$E$5:$E$104,MATCH($B16,Properties!$A$5:$A$104,0)),4),Settings!$A$22:$A$26,0))*Settings!$B$19+N($I16)*Settings!$B$9,IF($D16="Late cancel",INDEX(Properties!$L$5:$L$104,MATCH($B16,Properties!$A$5:$A$104,0))*Settings!$B$11,0))),0)) | P16: =IF($B16="","",$N16-$O16) | Q16: =IF($A16="","",DATE(YEAR($A16),MONTH($A16),1)) | R16: =IF($A16="","",$A16+MOD(6-WEEKDAY($A16),7)) | S16: =IF($B16="","",IF(AND($M16='Invoice Builder'!$C$5,$Q16='Invoice Builder'!$C$6,N($N16)>0),COUNTIFS($M$5:$M16,'Invoice Builder'!$C$5,$Q$5:$Q16,'Invoice Builder'!$C$6,$N$5:$N16,">0"),"")) | T16: =IF($A16="","",IF($A16>=DATE(YEAR($A16),4,6),YEAR($A16)&"/"&RIGHT(YEAR($A16)+1,2),YEAR($A16)-1&"/"&RIGHT(YEAR($A16),2)))
L17: =IF(OR($E17="",$F17=""),"",MOD($F17-$E17,1)*24) | M17: =IF($B17="","",IFERROR(INDEX(Properties!$D$5:$D$104,MATCH($B17,Properties!$A$5:$A$104,0)),"?")) | N17: =IF($B17="","",IFERROR(IF($D17="Completed",INDEX(Properties!$I$5:$I$104,MATCH($B17,Properties!$A$5:$A$104,0))*(1+IF($G17="Y",Settings!$B$8,0))+IF($H17="Y",Settings!$B$7,0)+N($I17),IF($D17="Deep clean",INDEX(Settings!$E$22:$E$26,MATCH(MIN(INDEX(Properties!$E$5:$E$104,MATCH($B17,Properties!$A$5:$A$104,0)),4),Settings!$A$22:$A$26,0))+N($I17),IF($D17="Late cancel",INDEX(Properties!$I$5:$I$104,MATCH($B17,Properties!$A$5:$A$104,0))*Settings!$B$10,0))),0)) | O17: =IF($B17="","",IFERROR(IF($D17="Completed",INDEX(Properties!$L$5:$L$104,MATCH($B17,Properties!$A$5:$A$104,0))+IF($G17="Y",INDEX(Properties!$I$5:$I$104,MATCH($B17,Properties!$A$5:$A$104,0))*Settings!$B$8*Settings!$B$9,0)+IF($H17="Y",Settings!$B$7*Settings!$B$9,0)+N($I17)*Settings!$B$9,IF($D17="Deep clean",INDEX(Settings!$E$22:$E$26,MATCH(MIN(INDEX(Properties!$E$5:$E$104,MATCH($B17,Properties!$A$5:$A$104,0)),4),Settings!$A$22:$A$26,0))*Settings!$B$19+N($I17)*Settings!$B$9,IF($D17="Late cancel",INDEX(Properties!$L$5:$L$104,MATCH($B17,Properties!$A$5:$A$104,0))*Settings!$B$11,0))),0)) | P17: =IF($B17="","",$N17-$O17) | Q17: =IF($A17="","",DATE(YEAR($A17),MONTH($A17),1)) | R17: =IF($A17="","",$A17+MOD(6-WEEKDAY($A17),7)) | S17: =IF($B17="","",IF(AND($M17='Invoice Builder'!$C$5,$Q17='Invoice Builder'!$C$6,N($N17)>0),COUNTIFS($M$5:$M17,'Invoice Builder'!$C$5,$Q$5:$Q17,'Invoice Builder'!$C$6,$N$5:$N17,">0"),"")) | T17: =IF($A17="","",IF($A17>=DATE(YEAR($A17),4,6),YEAR($A17)&"/"&RIGHT(YEAR($A17)+1,2),YEAR($A17)-1&"/"&RIGHT(YEAR($A17),2)))
L18: =IF(OR($E18="",$F18=""),"",MOD($F18-$E18,1)*24) | M18: =IF($B18="","",IFERROR(INDEX(Properties!$D$5:$D$104,MATCH($B18,Properties!$A$5:$A$104,0)),"?")) | N18: =IF($B18="","",IFERROR(IF($D18="Completed",INDEX(Properties!$I$5:$I$104,MATCH($B18,Properties!$A$5:$A$104,0))*(1+IF($G18="Y",Settings!$B$8,0))+IF($H18="Y",Settings!$B$7,0)+N($I18),IF($D18="Deep clean",INDEX(Settings!$E$22:$E$26,MATCH(MIN(INDEX(Properties!$E$5:$E$104,MATCH($B18,Properties!$A$5:$A$104,0)),4),Settings!$A$22:$A$26,0))+N($I18),IF($D18="Late cancel",INDEX(Properties!$I$5:$I$104,MATCH($B18,Properties!$A$5:$A$104,0))*Settings!$B$10,0))),0)) | O18: =IF($B18="","",IFERROR(IF($D18="Completed",INDEX(Properties!$L$5:$L$104,MATCH($B18,Properties!$A$5:$A$104,0))+IF($G18="Y",INDEX(Properties!$I$5:$I$104,MATCH($B18,Properties!$A$5:$A$104,0))*Settings!$B$8*Settings!$B$9,0)+IF($H18="Y",Settings!$B$7*Settings!$B$9,0)+N($I18)*Settings!$B$9,IF($D18="Deep clean",INDEX(Settings!$E$22:$E$26,MATCH(MIN(INDEX(Properties!$E$5:$E$104,MATCH($B18,Properties!$A$5:$A$104,0)),4),Settings!$A$22:$A$26,0))*Settings!$B$19+N($I18)*Settings!$B$9,IF($D18="Late cancel",INDEX(Properties!$L$5:$L$104,MATCH($B18,Properties!$A$5:$A$104,0))*Settings!$B$11,0))),0)) | P18: =IF($B18="","",$N18-$O18) | Q18: =IF($A18="","",DATE(YEAR($A18),MONTH($A18),1)) | R18: =IF($A18="","",$A18+MOD(6-WEEKDAY($A18),7)) | S18: =IF($B18="","",IF(AND($M18='Invoice Builder'!$C$5,$Q18='Invoice Builder'!$C$6,N($N18)>0),COUNTIFS($M$5:$M18,'Invoice Builder'!$C$5,$Q$5:$Q18,'Invoice Builder'!$C$6,$N$5:$N18,">0"),"")) | T18: =IF($A18="","",IF($A18>=DATE(YEAR($A18),4,6),YEAR($A18)&"/"&RIGHT(YEAR($A18)+1,2),YEAR($A18)-1&"/"&RIGHT(YEAR($A18),2)))
L19: =IF(OR($E19="",$F19=""),"",MOD($F19-$E19,1)*24) | M19: =IF($B19="","",IFERROR(INDEX(Properties!$D$5:$D$104,MATCH($B19,Properties!$A$5:$A$104,0)),"?")) | N19: =IF($B19="","",IFERROR(IF($D19="Completed",INDEX(Properties!$I$5:$I$104,MATCH($B19,Properties!$A$5:$A$104,0))*(1+IF($G19="Y",Settings!$B$8,0))+IF($H19="Y",Settings!$B$7,0)+N($I19),IF($D19="Deep clean",INDEX(Settings!$E$22:$E$26,MATCH(MIN(INDEX(Properties!$E$5:$E$104,MATCH($B19,Properties!$A$5:$A$104,0)),4),Settings!$A$22:$A$26,0))+N($I19),IF($D19="Late cancel",INDEX(Properties!$I$5:$I$104,MATCH($B19,Properties!$A$5:$A$104,0))*Settings!$B$10,0))),0)) | O19: =IF($B19="","",IFERROR(IF($D19="Completed",INDEX(Properties!$L$5:$L$104,MATCH($B19,Properties!$A$5:$A$104,0))+IF($G19="Y",INDEX(Properties!$I$5:$I$104,MATCH($B19,Properties!$A$5:$A$104,0))*Settings!$B$8*Settings!$B$9,0)+IF($H19="Y",Settings!$B$7*Settings!$B$9,0)+N($I19)*Settings!$B$9,IF($D19="Deep clean",INDEX(Settings!$E$22:$E$26,MATCH(MIN(INDEX(Properties!$E$5:$E$104,MATCH($B19,Properties!$A$5:$A$104,0)),4),Settings!$A$22:$A$26,0))*Settings!$B$19+N($I19)*Settings!$B$9,IF($D19="Late cancel",INDEX(Properties!$L$5:$L$104,MATCH($B19,Properties!$A$5:$A$104,0))*Settings!$B$11,0))),0)) | P19: =IF($B19="","",$N19-$O19) | Q19: =IF($A19="","",DATE(YEAR($A19),MONTH($A19),1)) | R19: =IF($A19="","",$A19+MOD(6-WEEKDAY($A19),7)) | S19: =IF($B19="","",IF(AND($M19='Invoice Builder'!$C$5,$Q19='Invoice Builder'!$C$6,N($N19)>0),COUNTIFS($M$5:$M19,'Invoice Builder'!$C$5,$Q$5:$Q19,'Invoice Builder'!$C$6,$N$5:$N19,">0"),"")) | T19: =IF($A19="","",IF($A19>=DATE(YEAR($A19),4,6),YEAR($A19)&"/"&RIGHT(YEAR($A19)+1,2),YEAR($A19)-1&"/"&RIGHT(YEAR($A19),2)))
L20: =IF(OR($E20="",$F20=""),"",MOD($F20-$E20,1)*24) | M20: =IF($B20="","",IFERROR(INDEX(Properties!$D$5:$D$104,MATCH($B20,Properties!$A$5:$A$104,0)),"?")) | N20: =IF($B20="","",IFERROR(IF($D20="Completed",INDEX(Properties!$I$5:$I$104,MATCH($B20,Properties!$A$5:$A$104,0))*(1+IF($G20="Y",Settings!$B$8,0))+IF($H20="Y",Settings!$B$7,0)+N($I20),IF($D20="Deep clean",INDEX(Settings!$E$22:$E$26,MATCH(MIN(INDEX(Properties!$E$5:$E$104,MATCH($B20,Properties!$A$5:$A$104,0)),4),Settings!$A$22:$A$26,0))+N($I20),IF($D20="Late cancel",INDEX(Properties!$I$5:$I$104,MATCH($B20,Properties!$A$5:$A$104,0))*Settings!$B$10,0))),0)) | O20: =IF($B20="","",IFERROR(IF($D20="Completed",INDEX(Properties!$L$5:$L$104,MATCH($B20,Properties!$A$5:$A$104,0))+IF($G20="Y",INDEX(Properties!$I$5:$I$104,MATCH($B20,Properties!$A$5:$A$104,0))*Settings!$B$8*Settings!$B$9,0)+IF($H20="Y",Settings!$B$7*Settings!$B$9,0)+N($I20)*Settings!$B$9,IF($D20="Deep clean",INDEX(Settings!$E$22:$E$26,MATCH(MIN(INDEX(Properties!$E$5:$E$104,MATCH($B20,Properties!$A$5:$A$104,0)),4),Settings!$A$22:$A$26,0))*Settings!$B$19+N($I20)*Settings!$B$9,IF($D20="Late cancel",INDEX(Properties!$L$5:$L$104,MATCH($B20,Properties!$A$5:$A$104,0))*Settings!$B$11,0))),0)) | P20: =IF($B20="","",$N20-$O20) | Q20: =IF($A20="","",DATE(YEAR($A20),MONTH($A20),1)) | R20: =IF($A20="","",$A20+MOD(6-WEEKDAY($A20),7)) | S20: =IF($B20="","",IF(AND($M20='Invoice Builder'!$C$5,$Q20='Invoice Builder'!$C$6,N($N20)>0),COUNTIFS($M$5:$M20,'Invoice Builder'!$C$5,$Q$5:$Q20,'Invoice Builder'!$C$6,$N$5:$N20,">0"),"")) | T20: =IF($A20="","",IF($A20>=DATE(YEAR($A20),4,6),YEAR($A20)&"/"&RIGHT(YEAR($A20)+1,2),YEAR($A20)-1&"/"&RIGHT(YEAR($A20),2)))
... L1004: =IF(OR($E1004="",$F1004=""),"",MOD($F1004-$E1004,1)*24) | M1004: =IF($B1004="","",IFERROR(INDEX(Properties!$D$5:$D$104,MATCH($B1004,Properties!$A$5:$A$104,0)),"?")) | N1004: =IF($B1004="","",IFERROR(IF($D1004="Completed",INDEX(Properties!$I$5:$I$104,MATCH($B1004,Properties!$A$5:$A$104,0))*(1+IF($G1004="Y",Settings!$B$8,0))+IF($H1004="Y",Settings!$B$7,0)+N($I1004),IF($D1004="Deep clean",INDEX(Settings!$E$22:$E$26,MATCH(MIN(INDEX(Properties!$E$5:$E$104,MATCH($B1004,Properties!$A$5:$A$104,0)),4),Settings!$A$22:$A$26,0))+N($I1004),IF($D1004="Late cancel",INDEX(Properties!$I$5:$I$104,MATCH($B1004,Properties!$A$5:$A$104,0))*Settings!$B$10,0))),0)) | O1004: =IF($B1004="","",IFERROR(IF($D1004="Completed",INDEX(Properties!$L$5:$L$104,MATCH($B1004,Properties!$A$5:$A$104,0))+IF($G1004="Y",INDEX(Properties!$I$5:$I$104,MATCH($B1004,Properties!$A$5:$A$104,0))*Settings!$B$8*Settings!$B$9,0)+IF($H1004="Y",Settings!$B$7*Settings!$B$9,0)+N($I1004)*Settings!$B$9,IF($D1004="Deep clean",INDEX(Settings!$E$22:$E$26,MATCH(MIN(INDEX(Properties!$E$5:$E$104,MATCH($B1004,Properties!$A$5:$A$104,0)),4),Settings!$A$22:$A$26,0))*Settings!$B$19+N($I1004)*Settings!$B$9,IF($D1004="Late cancel",INDEX(Properties!$L$5:$L$104,MATCH($B1004,Properties!$A$5:$A$104,0))*Settings!$B$11,0))),0)) | P1004: =IF($B1004="","",$N1004-$O1004) | Q1004: =IF($A1004="","",DATE(YEAR($A1004),MONTH($A1004),1)) | R1004: =IF($A1004="","",$A1004+MOD(6-WEEKDAY($A1004),7)) | S1004: =IF($B1004="","",IF(AND($M1004='Invoice Builder'!$C$5,$Q1004='Invoice Builder'!$C$6,N($N1004)>0),COUNTIFS($M$5:$M1004,'Invoice Builder'!$C$5,$Q$5:$Q1004,'Invoice Builder'!$C$6,$N$5:$N1004,">0"),"")) | T1004: =IF($A1004="","",IF($A1004>=DATE(YEAR($A1004),4,6),YEAR($A1004)&"/"&RIGHT(YEAR($A1004)+1,2),YEAR($A1004)-1&"/"&RIGHT(YEAR($A1004),2)))

Sheet Stock
A1: Stock per Property
A2: Full stock = what should be there after a clean. Update 'Count now' from the cleaner's counts. Red = buy before the next clean.
A4: Prop ID | B4: Item ID | C4: Item | D4: Full stock | E4: Reorder at or below | F4: Count now | G4: Last counted | H4: Status | I4: Need to buy | J4: Est. cost (£) | L4: Template for a new 2-bed: copy rows 5–21 and change the Prop ID. Scale full stock up or down for bigger or smaller places.
A5: P001 | B5: S01 | C5: =IF($B5="","",IFERROR(INDEX(Supplies!$B$5:$B$104,MATCH($B5,Supplies!$A$5:$A$104,0)),"?")) -> Toilet roll | D5: 8 | E5: 4 | F5: 5 | G5: 46319 | H5: =IF($A5="","",IF($F5="","Count it",IF($F5<=$E5,"REORDER","OK"))) -> OK | I5: =IF(OR($A5="",$F5=""),"",MAX(0,$D5-$F5)) -> 3 | J5: =IF(OR($A5="",$I5=""),"",$I5*IFERROR(INDEX(Supplies!$F$5:$F$104,MATCH($B5,Supplies!$A$5:$A$104,0)),0)) -> 1.575
A6: P001 | B6: S02 | C6: =IF($B6="","",IFERROR(INDEX(Supplies!$B$5:$B$104,MATCH($B6,Supplies!$A$5:$A$104,0)),"?")) -> Kitchen roll | D6: 3 | E6: 1 | F6: 2 | G6: 46319 | H6: =IF($A6="","",IF($F6="","Count it",IF($F6<=$E6,"REORDER","OK"))) -> OK | I6: =IF(OR($A6="",$F6=""),"",MAX(0,$D6-$F6)) -> 1 | J6: =IF(OR($A6="",$I6=""),"",$I6*IFERROR(INDEX(Supplies!$F$5:$F$104,MATCH($B6,Supplies!$A$5:$A$104,0)),0)) -> 1
A7: P001 | B7: S03 | C7: =IF($B7="","",IFERROR(INDEX(Supplies!$B$5:$B$104,MATCH($B7,Supplies!$A$5:$A$104,0)),"?")) -> Hand soap (500ml pump) | D7: 2 | E7: 1 | F7: 1 | G7: 46319 | H7: =IF($A7="","",IF($F7="","Count it",IF($F7<=$E7,"REORDER","OK"))) -> REORDER | I7: =IF(OR($A7="",$F7=""),"",MAX(0,$D7-$F7)) -> 1 | J7: =IF(OR($A7="",$I7=""),"",$I7*IFERROR(INDEX(Supplies!$F$5:$F$104,MATCH($B7,Supplies!$A$5:$A$104,0)),0)) -> 1.5
A8: P001 | B8: S04 | C8: =IF($B8="","",IFERROR(INDEX(Supplies!$B$5:$B$104,MATCH($B8,Supplies!$A$5:$A$104,0)),"?")) -> Mini shampoo | D8: 6 | E8: 2 | F8: 4 | G8: 46319 | H8: =IF($A8="","",IF($F8="","Count it",IF($F8<=$E8,"REORDER","OK"))) -> OK | I8: =IF(OR($A8="",$F8=""),"",MAX(0,$D8-$F8)) -> 2 | J8: =IF(OR($A8="",$I8=""),"",$I8*IFERROR(INDEX(Supplies!$F$5:$F$104,MATCH($B8,Supplies!$A$5:$A$104,0)),0)) -> 0.48
A9: P001 | B9: S05 | C9: =IF($B9="","",IFERROR(INDEX(Supplies!$B$5:$B$104,MATCH($B9,Supplies!$A$5:$A$104,0)),"?")) -> Mini conditioner | D9: 6 | E9: 2 | F9: 4 | G9: 46319 | H9: =IF($A9="","",IF($F9="","Count it",IF($F9<=$E9,"REORDER","OK"))) -> OK | I9: =IF(OR($A9="",$F9=""),"",MAX(0,$D9-$F9)) -> 2 | J9: =IF(OR($A9="",$I9=""),"",$I9*IFERROR(INDEX(Supplies!$F$5:$F$104,MATCH($B9,Supplies!$A$5:$A$104,0)),0)) -> 0.48
A10: P001 | B10: S06 | C10: =IF($B10="","",IFERROR(INDEX(Supplies!$B$5:$B$104,MATCH($B10,Supplies!$A$5:$A$104,0)),"?")) -> Mini shower gel | D10: 6 | E10: 2 | F10: 2 | G10: 46319 | H10: =IF($A10="","",IF($F10="","Count it",IF($F10<=$E10,"REORDER","OK"))) -> REORDER | I10: =IF(OR($A10="",$F10=""),"",MAX(0,$D10-$F10)) -> 4 | J10: =IF(OR($A10="",$I10=""),"",$I10*IFERROR(INDEX(Supplies!$F$5:$F$104,MATCH($B10,Supplies!$A$5:$A$104,0)),0)) -> 0.96
A11: P001 | B11: S07 | C11: =IF($B11="","",IFERROR(INDEX(Supplies!$B$5:$B$104,MATCH($B11,Supplies!$A$5:$A$104,0)),"?")) -> Dishwasher tablets | D11: 20 | E11: 8 | F11: 14 | G11: 46319 | H11: =IF($A11="","",IF($F11="","Count it",IF($F11<=$E11,"REORDER","OK"))) -> OK | I11: =IF(OR($A11="",$F11=""),"",MAX(0,$D11-$F11)) -> 6 | J11: =IF(OR($A11="",$I11=""),"",$I11*IFERROR(INDEX(Supplies!$F$5:$F$104,MATCH($B11,Supplies!$A$5:$A$104,0)),0)) -> 0.9
A12: P001 | B12: S08 | C12: =IF($B12="","",IFERROR(INDEX(Supplies!$B$5:$B$104,MATCH($B12,Supplies!$A$5:$A$104,0)),"?")) -> Washing-up liquid | D12: 2 | E12: 1 | F12: 2 | G12: 46319 | H12: =IF($A12="","",IF($F12="","Count it",IF($F12<=$E12,"REORDER","OK"))) -> OK | I12: =IF(OR($A12="",$F12=""),"",MAX(0,$D12-$F12)) -> 0 | J12: =IF(OR($A12="",$I12=""),"",$I12*IFERROR(INDEX(Supplies!$F$5:$F$104,MATCH($B12,Supplies!$A$5:$A$104,0)),0)) -> 0
A13: P001 | B13: S09 | C13: =IF($B13="","",IFERROR(INDEX(Supplies!$B$5:$B$104,MATCH($B13,Supplies!$A$5:$A$104,0)),"?")) -> Sponge scourers | D13: 3 | E13: 1 | F13: 2 | G13: 46319 | H13: =IF($A13="","",IF($F13="","Count it",IF($F13<=$E13,"REORDER","OK"))) -> OK | I13: =IF(OR($A13="",$F13=""),"",MAX(0,$D13-$F13)) -> 1 | J13: =IF(OR($A13="",$I13=""),"",$I13*IFERROR(INDEX(Supplies!$F$5:$F$104,MATCH($B13,Supplies!$A$5:$A$104,0)),0)) -> 0.3
A14: P001 | B14: S10 | C14: =IF($B14="","",IFERROR(INDEX(Supplies!$B$5:$B$104,MATCH($B14,Supplies!$A$5:$A$104,0)),"?")) -> Bin bags (kitchen) | D14: 20 | E14: 8 | F14: 7 | G14: 46319 | H14: =IF($A14="","",IF($F14="","Count it",IF($F14<=$E14,"REORDER","OK"))) -> REORDER | I14: =IF(OR($A14="",$F14=""),"",MAX(0,$D14-$F14)) -> 13 | J14: =IF(OR($A14="",$I14=""),"",$I14*IFERROR(INDEX(Supplies!$F$5:$F$104,MATCH($B14,Supplies!$A$5:$A$104,0)),0)) -> 1.04
A15: P001 | B15: S11 | C15: =IF($B15="","",IFERROR(INDEX(Supplies!$B$5:$B$104,MATCH($B15,Supplies!$A$5:$A$104,0)),"?")) -> Tea bags | D15: 40 | E15: 15 | F15: 22 | G15: 46319 | H15: =IF($A15="","",IF($F15="","Count it",IF($F15<=$E15,"REORDER","OK"))) -> OK | I15: =IF(OR($A15="",$F15=""),"",MAX(0,$D15-$F15)) -> 18 | J15: =IF(OR($A15="",$I15=""),"",$I15*IFERROR(INDEX(Supplies!$F$5:$F$104,MATCH($B15,Supplies!$A$5:$A$104,0)),0)) -> 0.45
A16: P001 | B16: S12 | C16: =IF($B16="","",IFERROR(INDEX(Supplies!$B$5:$B$104,MATCH($B16,Supplies!$A$5:$A$104,0)),"?")) -> Coffee sachets / pods | D16: 20 | E16: 8 | F16: 9 | G16: 46319 | H16: =IF($A16="","",IF($F16="","Count it",IF($F16<=$E16,"REORDER","OK"))) -> OK | I16: =IF(OR($A16="",$F16=""),"",MAX(0,$D16-$F16)) -> 11 | J16: =IF(OR($A16="",$I16=""),"",$I16*IFERROR(INDEX(Supplies!$F$5:$F$104,MATCH($B16,Supplies!$A$5:$A$104,0)),0)) -> 1.65
... A21: P001 | B21: S24 | C21: =IF($B21="","",IFERROR(INDEX(Supplies!$B$5:$B$104,MATCH($B21,Supplies!$A$5:$A$104,0)),"?")) -> AA batteries | D21: 4 | E21: 2 | F21: 4 | G21: 46319 | H21: =IF($A21="","",IF($F21="","Count it",IF($F21<=$E21,"REORDER","OK"))) -> OK | I21: =IF(OR($A21="",$F21=""),"",MAX(0,$D21-$F21)) -> 0 | J21: =IF(OR($A21="",$I21=""),"",$I21*IFERROR(INDEX(Supplies!$F$5:$F$104,MATCH($B21,Supplies!$A$5:$A$104,0)),0)) -> 0
C22: =IF($B22="","",IFERROR(INDEX(Supplies!$B$5:$B$104,MATCH($B22,Supplies!$A$5:$A$104,0)),"?")) | H22: =IF($A22="","",IF($F22="","Count it",IF($F22<=$E22,"REORDER","OK"))) | I22: =IF(OR($A22="",$F22=""),"",MAX(0,$D22-$F22)) | J22: =IF(OR($A22="",$I22=""),"",$I22*IFERROR(INDEX(Supplies!$F$5:$F$104,MATCH($B22,Supplies!$A$5:$A$104,0)),0))
C23: =IF($B23="","",IFERROR(INDEX(Supplies!$B$5:$B$104,MATCH($B23,Supplies!$A$5:$A$104,0)),"?")) | H23: =IF($A23="","",IF($F23="","Count it",IF($F23<=$E23,"REORDER","OK"))) | I23: =IF(OR($A23="",$F23=""),"",MAX(0,$D23-$F23)) | J23: =IF(OR($A23="",$I23=""),"",$I23*IFERROR(INDEX(Supplies!$F$5:$F$104,MATCH($B23,Supplies!$A$5:$A$104,0)),0))
C24: =IF($B24="","",IFERROR(INDEX(Supplies!$B$5:$B$104,MATCH($B24,Supplies!$A$5:$A$104,0)),"?")) | H24: =IF($A24="","",IF($F24="","Count it",IF($F24<=$E24,"REORDER","OK"))) | I24: =IF(OR($A24="",$F24=""),"",MAX(0,$D24-$F24)) | J24: =IF(OR($A24="",$I24=""),"",$I24*IFERROR(INDEX(Supplies!$F$5:$F$104,MATCH($B24,Supplies!$A$5:$A$104,0)),0))
C25: =IF($B25="","",IFERROR(INDEX(Supplies!$B$5:$B$104,MATCH($B25,Supplies!$A$5:$A$104,0)),"?")) | H25: =IF($A25="","",IF($F25="","Count it",IF($F25<=$E25,"REORDER","OK"))) | I25: =IF(OR($A25="",$F25=""),"",MAX(0,$D25-$F25)) | J25: =IF(OR($A25="",$I25=""),"",$I25*IFERROR(INDEX(Supplies!$F$5:$F$104,MATCH($B25,Supplies!$A$5:$A$104,0)),0))
C26: =IF($B26="","",IFERROR(INDEX(Supplies!$B$5:$B$104,MATCH($B26,Supplies!$A$5:$A$104,0)),"?")) | H26: =IF($A26="","",IF($F26="","Count it",IF($F26<=$E26,"REORDER","OK"))) | I26: =IF(OR($A26="",$F26=""),"",MAX(0,$D26-$F26)) | J26: =IF(OR($A26="",$I26=""),"",$I26*IFERROR(INDEX(Supplies!$F$5:$F$104,MATCH($B26,Supplies!$A$5:$A$104,0)),0))
C27: =IF($B27="","",IFERROR(INDEX(Supplies!$B$5:$B$104,MATCH($B27,Supplies!$A$5:$A$104,0)),"?")) | H27: =IF($A27="","",IF($F27="","Count it",IF($F27<=$E27,"REORDER","OK"))) | I27: =IF(OR($A27="",$F27=""),"",MAX(0,$D27-$F27)) | J27: =IF(OR($A27="",$I27=""),"",$I27*IFERROR(INDEX(Supplies!$F$5:$F$104,MATCH($B27,Supplies!$A$5:$A$104,0)),0))
C28: =IF($B28="","",IFERROR(INDEX(Supplies!$B$5:$B$104,MATCH($B28,Supplies!$A$5:$A$104,0)),"?")) | H28: =IF($A28="","",IF($F28="","Count it",IF($F28<=$E28,"REORDER","OK"))) | I28: =IF(OR($A28="",$F28=""),"",MAX(0,$D28-$F28)) | J28: =IF(OR($A28="",$I28=""),"",$I28*IFERROR(INDEX(Supplies!$F$5:$F$104,MATCH($B28,Supplies!$A$5:$A$104,0)),0))
C29: =IF($B29="","",IFERROR(INDEX(Supplies!$B$5:$B$104,MATCH($B29,Supplies!$A$5:$A$104,0)),"?")) | H29: =IF($A29="","",IF($F29="","Count it",IF($F29<=$E29,"REORDER","OK"))) | I29: =IF(OR($A29="",$F29=""),"",MAX(0,$D29-$F29)) | J29: =IF(OR($A29="",$I29=""),"",$I29*IFERROR(INDEX(Supplies!$F$5:$F$104,MATCH($B29,Supplies!$A$5:$A$104,0)),0))
C30: =IF($B30="","",IFERROR(INDEX(Supplies!$B$5:$B$104,MATCH($B30,Supplies!$A$5:$A$104,0)),"?")) | H30: =IF($A30="","",IF($F30="","Count it",IF($F30<=$E30,"REORDER","OK"))) | I30: =IF(OR($A30="",$F30=""),"",MAX(0,$D30-$F30)) | J30: =IF(OR($A30="",$I30=""),"",$I30*IFERROR(INDEX(Supplies!$F$5:$F$104,MATCH($B30,Supplies!$A$5:$A$104,0)),0))
C31: =IF($B31="","",IFERROR(INDEX(Supplies!$B$5:$B$104,MATCH($B31,Supplies!$A$5:$A$104,0)),"?")) | H31: =IF($A31="","",IF($F31="","Count it",IF($F31<=$E31,"REORDER","OK"))) | I31: =IF(OR($A31="",$F31=""),"",MAX(0,$D31-$F31)) | J31: =IF(OR($A31="",$I31=""),"",$I31*IFERROR(INDEX(Supplies!$F$5:$F$104,MATCH($B31,Supplies!$A$5:$A$104,0)),0))
C32: =IF($B32="","",IFERROR(INDEX(Supplies!$B$5:$B$104,MATCH($B32,Supplies!$A$5:$A$104,0)),"?")) | H32: =IF($A32="","",IF($F32="","Count it",IF($F32<=$E32,"REORDER","OK"))) | I32: =IF(OR($A32="",$F32=""),"",MAX(0,$D32-$F32)) | J32: =IF(OR($A32="",$I32=""),"",$I32*IFERROR(INDEX(Supplies!$F$5:$F$104,MATCH($B32,Supplies!$A$5:$A$104,0)),0))
C33: =IF($B33="","",IFERROR(INDEX(Supplies!$B$5:$B$104,MATCH($B33,Supplies!$A$5:$A$104,0)),"?")) | H33: =IF($A33="","",IF($F33="","Count it",IF($F33<=$E33,"REORDER","OK"))) | I33: =IF(OR($A33="",$F33=""),"",MAX(0,$D33-$F33)) | J33: =IF(OR($A33="",$I33=""),"",$I33*IFERROR(INDEX(Supplies!$F$5:$F$104,MATCH($B33,Supplies!$A$5:$A$104,0)),0))
... C504: =IF($B504="","",IFERROR(INDEX(Supplies!$B$5:$B$104,MATCH($B504,Supplies!$A$5:$A$104,0)),"?")) | H504: =IF($A504="","",IF($F504="","Count it",IF($F504<=$E504,"REORDER","OK"))) | I504: =IF(OR($A504="",$F504=""),"",MAX(0,$D504-$F504)) | J504: =IF(OR($A504="",$I504=""),"",$I504*IFERROR(INDEX(Supplies!$F$5:$F$104,MATCH($B504,Supplies!$A$5:$A$104,0)),0))

Sheet Purchases
A1: Purchases & Replacements
A2: Everything you buy for a property. Charge host = Y adds it to their invoice at cost + markup. Keep every receipt (photo is fine).
A4: Date | B4: Prop ID | C4: Item ID (optional) | D4: What | E4: Qty | F4: Total cost (£, from receipt) | G4: Type | H4: Charge host? (Y/N) | I4: Host approved? (Y/N) | J4: Receipt saved? (Y/N) | K4: Notes | L4: Host ID | M4: Cost each (£) | N4: Charge to host (£) | O4: Check | P4: Month | Q4: Invoice line # | R4: Tax year
A5: 46304 | B5: P001 | C5: S22 | D5: LED bulb E27 | E5: 1 | F5: 1.5 | G5: Replacement | H5: Y | J5: Y | K5: EXAMPLE: bedside lamp | L5: =IF($B5="","",IFERROR(INDEX(Properties!$D$5:$D$104,MATCH($B5,Properties!$A$5:$A$104,0)),"-")) -> H001 | M5: =IF(OR($A5="",N($E5)=0),"",$F5/$E5) -> 1.5 | N5: =IF($A5="","",IF($H5="Y",$F5*(1+Settings!$B$3),0)) -> 1.65 | O5: =IF($A5="","",IF(AND($H5="Y",$G5<>"Restock",N($M5)>Settings!$B$4,$I5<>"Y"),"Get host OK",IF(AND($H5="Y",$F5>Settings!$B$5,$I5<>"Y"),"Host should pay upfront",IF($J5<>"Y","Save receipt","OK")))) -> OK | P5: =IF($A5="","",DATE(YEAR($A5),MONTH($A5),1)) -> 46296 | Q5: =IF($A5="","",IF(AND($L5='Invoice Builder'!$C$5,$P5='Invoice Builder'!$C$6,N($N5)>0),COUNTIFS($L$5:$L5,'Invoice Builder'!$C$5,$P$5:$P5,'Invoice Builder'!$C$6,$N$5:$N5,">0"),"")) -> 1 | R5: =IF($A5="","",IF($A5>=DATE(YEAR($A5),4,6),YEAR($A5)&"/"&RIGHT(YEAR($A5)+1,2),YEAR($A5)-1&"/"&RIGHT(YEAR($A5),2))) -> 2026/27
A6: 46320 | B6: P001 | C6: S14 | D6: UHT milk portions | E6: 12 | F6: 0.9 | G6: Restock | H6: Y | J6: Y | K6: EXAMPLE | L6: =IF($B6="","",IFERROR(INDEX(Properties!$D$5:$D$104,MATCH($B6,Properties!$A$5:$A$104,0)),"-")) -> H001 | M6: =IF(OR($A6="",N($E6)=0),"",$F6/$E6) -> 0.075 | N6: =IF($A6="","",IF($H6="Y",$F6*(1+Settings!$B$3),0)) -> 0.99 | O6: =IF($A6="","",IF(AND($H6="Y",$G6<>"Restock",N($M6)>Settings!$B$4,$I6<>"Y"),"Get host OK",IF(AND($H6="Y",$F6>Settings!$B$5,$I6<>"Y"),"Host should pay upfront",IF($J6<>"Y","Save receipt","OK")))) -> OK | P6: =IF($A6="","",DATE(YEAR($A6),MONTH($A6),1)) -> 46296 | Q6: =IF($A6="","",IF(AND($L6='Invoice Builder'!$C$5,$P6='Invoice Builder'!$C$6,N($N6)>0),COUNTIFS($L$5:$L6,'Invoice Builder'!$C$5,$P$5:$P6,'Invoice Builder'!$C$6,$N$5:$N6,">0"),"")) -> 2 | R6: =IF($A6="","",IF($A6>=DATE(YEAR($A6),4,6),YEAR($A6)&"/"&RIGHT(YEAR($A6)+1,2),YEAR($A6)-1&"/"&RIGHT(YEAR($A6),2))) -> 2026/27
A7: 46320 | B7: P001 | C7: S25 | D7: Wine glasses (guest broke 2) | E7: 2 | F7: 4 | G7: Guest damage | H7: Y | I7: Y | J7: Y | K7: EXAMPLE: see Damage tab | L7: =IF($B7="","",IFERROR(INDEX(Properties!$D$5:$D$104,MATCH($B7,Properties!$A$5:$A$104,0)),"-")) -> H001 | M7: =IF(OR($A7="",N($E7)=0),"",$F7/$E7) -> 2 | N7: =IF($A7="","",IF($H7="Y",$F7*(1+Settings!$B$3),0)) -> 4.4 | O7: =IF($A7="","",IF(AND($H7="Y",$G7<>"Restock",N($M7)>Settings!$B$4,$I7<>"Y"),"Get host OK",IF(AND($H7="Y",$F7>Settings!$B$5,$I7<>"Y"),"Host should pay upfront",IF($J7<>"Y","Save receipt","OK")))) -> OK | P7: =IF($A7="","",DATE(YEAR($A7),MONTH($A7),1)) -> 46296 | Q7: =IF($A7="","",IF(AND($L7='Invoice Builder'!$C$5,$P7='Invoice Builder'!$C$6,N($N7)>0),COUNTIFS($L$5:$L7,'Invoice Builder'!$C$5,$P$5:$P7,'Invoice Builder'!$C$6,$N$5:$N7,">0"),"")) -> 3 | R7: =IF($A7="","",IF($A7>=DATE(YEAR($A7),4,6),YEAR($A7)&"/"&RIGHT(YEAR($A7)+1,2),YEAR($A7)-1&"/"&RIGHT(YEAR($A7),2))) -> 2026/27
L8: =IF($B8="","",IFERROR(INDEX(Properties!$D$5:$D$104,MATCH($B8,Properties!$A$5:$A$104,0)),"-")) | M8: =IF(OR($A8="",N($E8)=0),"",$F8/$E8) | N8: =IF($A8="","",IF($H8="Y",$F8*(1+Settings!$B$3),0)) | O8: =IF($A8="","",IF(AND($H8="Y",$G8<>"Restock",N($M8)>Settings!$B$4,$I8<>"Y"),"Get host OK",IF(AND($H8="Y",$F8>Settings!$B$5,$I8<>"Y"),"Host should pay upfront",IF($J8<>"Y","Save receipt","OK")))) | P8: =IF($A8="","",DATE(YEAR($A8),MONTH($A8),1)) | Q8: =IF($A8="","",IF(AND($L8='Invoice Builder'!$C$5,$P8='Invoice Builder'!$C$6,N($N8)>0),COUNTIFS($L$5:$L8,'Invoice Builder'!$C$5,$P$5:$P8,'Invoice Builder'!$C$6,$N$5:$N8,">0"),"")) | R8: =IF($A8="","",IF($A8>=DATE(YEAR($A8),4,6),YEAR($A8)&"/"&RIGHT(YEAR($A8)+1,2),YEAR($A8)-1&"/"&RIGHT(YEAR($A8),2)))
L9: =IF($B9="","",IFERROR(INDEX(Properties!$D$5:$D$104,MATCH($B9,Properties!$A$5:$A$104,0)),"-")) | M9: =IF(OR($A9="",N($E9)=0),"",$F9/$E9) | N9: =IF($A9="","",IF($H9="Y",$F9*(1+Settings!$B$3),0)) | O9: =IF($A9="","",IF(AND($H9="Y",$G9<>"Restock",N($M9)>Settings!$B$4,$I9<>"Y"),"Get host OK",IF(AND($H9="Y",$F9>Settings!$B$5,$I9<>"Y"),"Host should pay upfront",IF($J9<>"Y","Save receipt","OK")))) | P9: =IF($A9="","",DATE(YEAR($A9),MONTH($A9),1)) | Q9: =IF($A9="","",IF(AND($L9='Invoice Builder'!$C$5,$P9='Invoice Builder'!$C$6,N($N9)>0),COUNTIFS($L$5:$L9,'Invoice Builder'!$C$5,$P$5:$P9,'Invoice Builder'!$C$6,$N$5:$N9,">0"),"")) | R9: =IF($A9="","",IF($A9>=DATE(YEAR($A9),4,6),YEAR($A9)&"/"&RIGHT(YEAR($A9)+1,2),YEAR($A9)-1&"/"&RIGHT(YEAR($A9),2)))
L10: =IF($B10="","",IFERROR(INDEX(Properties!$D$5:$D$104,MATCH($B10,Properties!$A$5:$A$104,0)),"-")) | M10: =IF(OR($A10="",N($E10)=0),"",$F10/$E10) | N10: =IF($A10="","",IF($H10="Y",$F10*(1+Settings!$B$3),0)) | O10: =IF($A10="","",IF(AND($H10="Y",$G10<>"Restock",N($M10)>Settings!$B$4,$I10<>"Y"),"Get host OK",IF(AND($H10="Y",$F10>Settings!$B$5,$I10<>"Y"),"Host should pay upfront",IF($J10<>"Y","Save receipt","OK")))) | P10: =IF($A10="","",DATE(YEAR($A10),MONTH($A10),1)) | Q10: =IF($A10="","",IF(AND($L10='Invoice Builder'!$C$5,$P10='Invoice Builder'!$C$6,N($N10)>0),COUNTIFS($L$5:$L10,'Invoice Builder'!$C$5,$P$5:$P10,'Invoice Builder'!$C$6,$N$5:$N10,">0"),"")) | R10: =IF($A10="","",IF($A10>=DATE(YEAR($A10),4,6),YEAR($A10)&"/"&RIGHT(YEAR($A10)+1,2),YEAR($A10)-1&"/"&RIGHT(YEAR($A10),2)))
L11: =IF($B11="","",IFERROR(INDEX(Properties!$D$5:$D$104,MATCH($B11,Properties!$A$5:$A$104,0)),"-")) | M11: =IF(OR($A11="",N($E11)=0),"",$F11/$E11) | N11: =IF($A11="","",IF($H11="Y",$F11*(1+Settings!$B$3),0)) | O11: =IF($A11="","",IF(AND($H11="Y",$G11<>"Restock",N($M11)>Settings!$B$4,$I11<>"Y"),"Get host OK",IF(AND($H11="Y",$F11>Settings!$B$5,$I11<>"Y"),"Host should pay upfront",IF($J11<>"Y","Save receipt","OK")))) | P11: =IF($A11="","",DATE(YEAR($A11),MONTH($A11),1)) | Q11: =IF($A11="","",IF(AND($L11='Invoice Builder'!$C$5,$P11='Invoice Builder'!$C$6,N($N11)>0),COUNTIFS($L$5:$L11,'Invoice Builder'!$C$5,$P$5:$P11,'Invoice Builder'!$C$6,$N$5:$N11,">0"),"")) | R11: =IF($A11="","",IF($A11>=DATE(YEAR($A11),4,6),YEAR($A11)&"/"&RIGHT(YEAR($A11)+1,2),YEAR($A11)-1&"/"&RIGHT(YEAR($A11),2)))
L12: =IF($B12="","",IFERROR(INDEX(Properties!$D$5:$D$104,MATCH($B12,Properties!$A$5:$A$104,0)),"-")) | M12: =IF(OR($A12="",N($E12)=0),"",$F12/$E12) | N12: =IF($A12="","",IF($H12="Y",$F12*(1+Settings!$B$3),0)) | O12: =IF($A12="","",IF(AND($H12="Y",$G12<>"Restock",N($M12)>Settings!$B$4,$I12<>"Y"),"Get host OK",IF(AND($H12="Y",$F12>Settings!$B$5,$I12<>"Y"),"Host should pay upfront",IF($J12<>"Y","Save receipt","OK")))) | P12: =IF($A12="","",DATE(YEAR($A12),MONTH($A12),1)) | Q12: =IF($A12="","",IF(AND($L12='Invoice Builder'!$C$5,$P12='Invoice Builder'!$C$6,N($N12)>0),COUNTIFS($L$5:$L12,'Invoice Builder'!$C$5,$P$5:$P12,'Invoice Builder'!$C$6,$N$5:$N12,">0"),"")) | R12: =IF($A12="","",IF($A12>=DATE(YEAR($A12),4,6),YEAR($A12)&"/"&RIGHT(YEAR($A12)+1,2),YEAR($A12)-1&"/"&RIGHT(YEAR($A12),2)))
L13: =IF($B13="","",IFERROR(INDEX(Properties!$D$5:$D$104,MATCH($B13,Properties!$A$5:$A$104,0)),"-")) | M13: =IF(OR($A13="",N($E13)=0),"",$F13/$E13) | N13: =IF($A13="","",IF($H13="Y",$F13*(1+Settings!$B$3),0)) | O13: =IF($A13="","",IF(AND($H13="Y",$G13<>"Restock",N($M13)>Settings!$B$4,$I13<>"Y"),"Get host OK",IF(AND($H13="Y",$F13>Settings!$B$5,$I13<>"Y"),"Host should pay upfront",IF($J13<>"Y","Save receipt","OK")))) | P13: =IF($A13="","",DATE(YEAR($A13),MONTH($A13),1)) | Q13: =IF($A13="","",IF(AND($L13='Invoice Builder'!$C$5,$P13='Invoice Builder'!$C$6,N($N13)>0),COUNTIFS($L$5:$L13,'Invoice Builder'!$C$5,$P$5:$P13,'Invoice Builder'!$C$6,$N$5:$N13,">0"),"")) | R13: =IF($A13="","",IF($A13>=DATE(YEAR($A13),4,6),YEAR($A13)&"/"&RIGHT(YEAR($A13)+1,2),YEAR($A13)-1&"/"&RIGHT(YEAR($A13),2)))
L14: =IF($B14="","",IFERROR(INDEX(Properties!$D$5:$D$104,MATCH($B14,Properties!$A$5:$A$104,0)),"-")) | M14: =IF(OR($A14="",N($E14)=0),"",$F14/$E14) | N14: =IF($A14="","",IF($H14="Y",$F14*(1+Settings!$B$3),0)) | O14: =IF($A14="","",IF(AND($H14="Y",$G14<>"Restock",N($M14)>Settings!$B$4,$I14<>"Y"),"Get host OK",IF(AND($H14="Y",$F14>Settings!$B$5,$I14<>"Y"),"Host should pay upfront",IF($J14<>"Y","Save receipt","OK")))) | P14: =IF($A14="","",DATE(YEAR($A14),MONTH($A14),1)) | Q14: =IF($A14="","",IF(AND($L14='Invoice Builder'!$C$5,$P14='Invoice Builder'!$C$6,N($N14)>0),COUNTIFS($L$5:$L14,'Invoice Builder'!$C$5,$P$5:$P14,'Invoice Builder'!$C$6,$N$5:$N14,">0"),"")) | R14: =IF($A14="","",IF($A14>=DATE(YEAR($A14),4,6),YEAR($A14)&"/"&RIGHT(YEAR($A14)+1,2),YEAR($A14)-1&"/"&RIGHT(YEAR($A14),2)))
L15: =IF($B15="","",IFERROR(INDEX(Properties!$D$5:$D$104,MATCH($B15,Properties!$A$5:$A$104,0)),"-")) | M15: =IF(OR($A15="",N($E15)=0),"",$F15/$E15) | N15: =IF($A15="","",IF($H15="Y",$F15*(1+Settings!$B$3),0)) | O15: =IF($A15="","",IF(AND($H15="Y",$G15<>"Restock",N($M15)>Settings!$B$4,$I15<>"Y"),"Get host OK",IF(AND($H15="Y",$F15>Settings!$B$5,$I15<>"Y"),"Host should pay upfront",IF($J15<>"Y","Save receipt","OK")))) | P15: =IF($A15="","",DATE(YEAR($A15),MONTH($A15),1)) | Q15: =IF($A15="","",IF(AND($L15='Invoice Builder'!$C$5,$P15='Invoice Builder'!$C$6,N($N15)>0),COUNTIFS($L$5:$L15,'Invoice Builder'!$C$5,$P$5:$P15,'Invoice Builder'!$C$6,$N$5:$N15,">0"),"")) | R15: =IF($A15="","",IF($A15>=DATE(YEAR($A15),4,6),YEAR($A15)&"/"&RIGHT(YEAR($A15)+1,2),YEAR($A15)-1&"/"&RIGHT(YEAR($A15),2)))
L16: =IF($B16="","",IFERROR(INDEX(Properties!$D$5:$D$104,MATCH($B16,Properties!$A$5:$A$104,0)),"-")) | M16: =IF(OR($A16="",N($E16)=0),"",$F16/$E16) | N16: =IF($A16="","",IF($H16="Y",$F16*(1+Settings!$B$3),0)) | O16: =IF($A16="","",IF(AND($H16="Y",$G16<>"Restock",N($M16)>Settings!$B$4,$I16<>"Y"),"Get host OK",IF(AND($H16="Y",$F16>Settings!$B$5,$I16<>"Y"),"Host should pay upfront",IF($J16<>"Y","Save receipt","OK")))) | P16: =IF($A16="","",DATE(YEAR($A16),MONTH($A16),1)) | Q16: =IF($A16="","",IF(AND($L16='Invoice Builder'!$C$5,$P16='Invoice Builder'!$C$6,N($N16)>0),COUNTIFS($L$5:$L16,'Invoice Builder'!$C$5,$P$5:$P16,'Invoice Builder'!$C$6,$N$5:$N16,">0"),"")) | R16: =IF($A16="","",IF($A16>=DATE(YEAR($A16),4,6),YEAR($A16)&"/"&RIGHT(YEAR($A16)+1,2),YEAR($A16)-1&"/"&RIGHT(YEAR($A16),2)))
